Workbook

Sheet BUSCA
Z1: SEGURADORAS_LISTA
B2: SISTEMA DE BUSCA DE SEGURADORAS | Z2: AIG Seguros
B3: Digite o nome da seguradora na célula amarela abaixo para visualizar seus dados | Z3: Akad Seguros
Z4: Alba- Aliança da Bahia
B5: Seguradora: | C5: AIG Seguros | D5: ← Digite ou selecione uma seguradora da lista | Z5: Alianz
Z6: Avla Seguradora
B7: ══════════════════════════════════════════════════════════════════════════════════════════ | Z7: Axa Seguros
B8: 📋 INFORMAÇÕES DA SEGURADORA SELECIONADA | Z8: Berkley Seguros
Z9: BMG Seguros
B10: 📁 PROPERTY (SLA) - Dados da Seguradora | Z10: Bradesco Seguros
Z11: Chubb Seguros
B12: Sistema | C12: =IF($C$5="","",IFERROR(VLOOKUP($C$5,'PROPERTY (SLA)'!$A:$Z,2,FALSE),"Não encontrado")) -> Não | Z12: Excelsor Seguros
B13: Trocar assunto do e-mail | C13: =IF($C$5="","",IFERROR(VLOOKUP($C$5,'PROPERTY (SLA)'!$A:$Z,3,FALSE),"Não encontrado")) -> Sem orientação a respeito Seguir padrão da Addvalora | Z13: FairFax Seguros
B14: Copiar analista nos e-mails | C14: =IF($C$5="","",IFERROR(VLOOKUP($C$5,'PROPERTY (SLA)'!$A:$Z,4,FALSE),"Não encontrado")) -> Sim | Z14: Fator
B15: SLA - 1º Contato e Agendamento | C15: =IF($C$5="","",IFERROR(VLOOKUP($C$5,'PROPERTY (SLA)'!$A:$Z,5,FALSE),"Não encontrado")) -> Orientação : Manter contato imediato após o recebimento do acionamento | Z15: FM Global
B16: SLA - Realização da Vistoria | C16: =IF($C$5="","",IFERROR(VLOOKUP($C$5,'PROPERTY (SLA)'!$A:$Z,6,FALSE),"Não encontrado")) -> Conforme agendamento / apresentar a sintese até 48h após a vistoria | Z16: Generali Seguros
B17: SLA - Relatório Preliminar | C17: =IF($C$5="","",IFERROR(VLOOKUP($C$5,'PROPERTY (SLA)'!$A:$Z,7,FALSE),"Não encontrado")) -> Até 5 dias após a vistoria | Z17: HDI Global
B18: SLA - Relatório Final | C18: =IF($C$5="","",IFERROR(VLOOKUP($C$5,'PROPERTY (SLA)'!$A:$Z,8,FALSE),"Não encontrado")) -> Até 7 dias após último documento | Z18: HDI Seguros
B19: Relatório modelo próprio | C19: =IF($C$5="","",IFERROR(VLOOKUP($C$5,'PROPERTY (SLA)'!$A:$Z,9,FALSE),"Não encontrado")) -> Não | Z19: Junto Seguros
B20: Períodos reiterações documentos | C20: =IF($C$5="","",IFERROR(VLOOKUP($C$5,'PROPERTY (SLA)'!$A:$Z,11,FALSE),"Não encontrado")) -> Sem orientação Sugestão: Reiterar a cada 10 dias | Z20: Liberty Seguros
B21: Prazo de encerramento | C21: =IF($C$5="","",IFERROR(VLOOKUP($C$5,'PROPERTY (SLA)'!$A:$Z,12,FALSE),"Não encontrado")) -> Sem informação / Sugestão: Confirmar com analista após 75 dias, se da continuidade ao processo | Z21: Mapfre
B22: Depreciação | C22: =IF($C$5="","",IFERROR(VLOOKUP($C$5,'PROPERTY (SLA)'!$A:$Z,13,FALSE),"Não encontrado")) -> Conforme apólice | Z22: Mitsui Seguros
B23: Salvados | C23: =IF($C$5="","",IFERROR(VLOOKUP($C$5,'PROPERTY (SLA)'!$A:$Z,15,FALSE),"Não encontrado")) -> Sem informação / E-mail para o analista | Z23: Newe
B24: Formulários Próprios | C24: =IF($C$5="","",IFERROR(VLOOKUP($C$5,'PROPERTY (SLA)'!$A:$Z,23,FALSE),"Não encontrado")) -> *Autorização de crédito *Declaração de outros seguros *Formulário de conformidade | Z24: Potencial Seguros
B25: Outros procedimentos | C25: =IF($C$5="","",IFERROR(VLOOKUP($C$5,'PROPERTY (SLA)'!$A:$Z,26,FALSE),"Não encontrado")) -> * Relatórios Preliminares 2,3,4....: A cada 30 dias, se houver informações que justifiquem, ou sempre que houver fatos relevantes, como alteração de Estimativas de indenização. Procedimentos e Honorários: Para valores de time sheet de até R$ 20.000,00, não há necessidade de aprovação prévia da AIG. | Z25: QBE Seguros
Z26: Sancor Seguros
Z27: Sombrero Seguros
B28: 📁 RCG (SLA) - Responsabilidade Civil Geral | Z28: Sompo Seguros
Z29: Sompo Seguros / TERCEIRIZAÇÃO ANÁLISE
B30: Sistema: | C30: =IF($C$5="","",IFERROR(VLOOKUP($C$5,'RCG (SLA)'!$A:$Z,2,FALSE),"Não disponível nesta categoria")) -> Não disponível nesta categoria | Z30: Sura Seguros
B31: Copiar analista: | C31: =IF($C$5="","",IFERROR(VLOOKUP($C$5,'RCG (SLA)'!$A:$Z,4,FALSE),"Não disponível nesta categoria")) -> Não disponível nesta categoria | Z31: Swiss Re
B32: SLA 1º Contato: | C32: =IF($C$5="","",IFERROR(VLOOKUP($C$5,'RCG (SLA)'!$A:$Z,5,FALSE),"Não disponível nesta categoria")) -> Não disponível nesta categoria | Z32: Tokio Marine
B33: SLA Relatório Final: | C33: =IF($C$5="","",IFERROR(VLOOKUP($C$5,'RCG (SLA)'!$A:$Z,8,FALSE),"Não disponível nesta categoria")) -> Não disponível nesta categoria | Z33: Zurich Seguros
B34: Prazo encerramento: | C34: =IF($C$5="","",IFERROR(VLOOKUP($C$5,'RCG (SLA)'!$A:$Z,12,FALSE),"Não disponível nesta categoria")) -> Não disponível nesta categoria
B35: Outros procedimentos: | C35: =IF($C$5="","",IFERROR(VLOOKUP($C$5,'RCG (SLA)'!$A:$Z,25,FALSE),"Não disponível nesta categoria")) -> Não disponível nesta categoria
B38: 📁 RCP (SLA) - Responsabilidade Civil Profissional
B40: Sistema: | C40: =IF($C$5="","",IFERROR(VLOOKUP($C$5,'RCP (SLA)'!$A:$Z,2,FALSE),"Não disponível nesta categoria")) -> Não disponível nesta categoria
B41: Copiar analista: | C41: =IF($C$5="","",IFERROR(VLOOKUP($C$5,'RCP (SLA)'!$A:$Z,4,FALSE),"Não disponível nesta categoria")) -> Não disponível nesta categoria
B42: SLA 1º Contato: | C42: =IF($C$5="","",IFERROR(VLOOKUP($C$5,'RCP (SLA)'!$A:$Z,5,FALSE),"Não disponível nesta categoria")) -> Não disponível nesta categoria
B43: SLA Relatório Final: | C43: =IF($C$5="","",IFERROR(VLOOKUP($C$5,'RCP (SLA)'!$A:$Z,8,FALSE),"Não disponível nesta categoria")) -> Não disponível nesta categoria
...

Sheet PROPERTY (SLA)
A1: Seguradora | B1: Sistema | C1: Trocar campo de assunto do e-mail | D1: Copiar o analista em todos os e-mails | E1: SLA - 1º Contato e agendamento vistoria | F1: SLA- Realização da vistoria / Síntese | G1: SLA - Relatório Preliminar | H1: SLA - Relatório Final | I1: Relatório de regulação modelo próprio | J1: Cronologia no relatório (sugestão utilizar em todos os processos) | K1: Períodos para reiterações de documentos (SLA) | L1: Prazo de encerramento sem manifestação / documentos- (Cycle Time) | M1: Depreciação | N1: Valor em Risco | O1: Salvados | Q1: Apresentação da apuração ao segurado antes da seguradora analisar os valores | R1: Emissão termo de acordo / demonstrativo de prejuízos | U1: Precisa enviar relatório final junto com time sheet / despesas | V1: Envio do relatório final junto com a nota fiscal | W1: Formulários Próprios | X1: Emissão carta de encerramento / Negativa | Z1: Outros procedimentos e assuntos
M2: Reter a D.V.N | O2: Área de Salvados | P2: Sistema | R2: Regulação | S2: Seguradora | T2: Modelo próprio | X2: Regulação | Y2: Seguradora
A3: AIG Seguros | B3: Não | C3: Sem orientação a respeito Seguir padrão da Addvalora | D3: Sim | E3: Orientação : Manter contato imediato após o recebimento do acionamento | F3: Conforme agendamento / apresentar a sintese até 48h após a vistoria | G3: Até 5 dias após a vistoria | H3: Até 7 dias após último documento | I3: Não | J3: Sim | K3: Sem orientação Sugestão: Reiterar a cada 10 dias | L3: Sem informação / Sugestão: Confirmar com analista após 75 dias, se da continuidade ao processo | M3: Conforme apólice | N3: E-mail para analista para ver se levanta o VR para prejuízos de até 5% do Valor em Risco Declarado ou atuar conforme particularidades da apólice Obs. Tem apólice que até determinado valor não apura o VR | O3: Sem informação / E-mail para o analista | P3: Sem informação | Q3: Sem orientação / ver com o analista | U3: Sem orientação a respeito | V3: Sem orientação a respeito | W3: *Autorização de crédito *Declaração de outros seguros *Formulário de conformidade | X3: Não | Y3: Sim | Z3: * Relatórios Preliminares 2,3,4....: A cada 30 dias, se houver informações que justifiquem, ou sempre que houver fatos relevantes, como alteração de Estimativas de indenização. Procedimentos e Honorários: Para valores de time sheet de até R$ 20.000,00, não há necessidade de aprovação prévia da AIG.
A4: Akad Seguros | B4: Sim | C4: Sem orientação a respeito Seguir padrão da Addvalora | D4: Não | E4: Orientação : Manter contato imediato após o recebimento do acionamento | F4: Conforme agendamento / apresentar a sintese até 48h após a vistoria | G4: Até 5 dias após a vistoria | H4: Até 5 dias após último documento | I4: Sim: Para prejuizos ate 300K / Prejuizos acima de 301K Modelo addvalora Property | J4: Sim | K4: A cada 05 dias | L4: 25 dias corridos (encerrar por falta de cobertura se sem documentos no 20º dia). | M4: Conforme apólice | N4: E-mail para analista para ver se levanta o VR para prejuízos de até 5% do Valor em Risco Declarado ou atuar conforme particularidades da apólice Obs. Tem apólice que até determinado valor não apura o VR | O4: Sem informação / E-mail para o analista | P4: Sem informação | Q4: Prejuizo ate 75K apresentar ao corretor/segurado sem análise prévia da Seguradora / Prejuizo acima de 75K somente após a analise e autorização da Seguradora | R4: Não | S4: Sim | T4: Sim | U4: Não | V4: Não | W4: Formulario PF / PJ | X4: Sim | Y4: Sim | Z4: *Consulta de prêmio no Digital para verificar se tem parcela pendente – se tiver pendência realizar a o cálculo de prazo curto (planilha em anexo); * Ao realizar espelhamento manter o analista em cópia para conhecimento da nova abertura. *Obrigatório Protocolo da Concessionária de Energia em caso de Danos Elétricos *Processo acima de 300 mil, fazer no relatório padrão Addvalora * Outros valores tem relatório simplificado * Pedidos de cadastros de dados bancários e cópia de apólices, devems ser direcionados à @Maria Souza, copiando as analistas @Isabella Silva e @Jemilli Silva. Não sendo necessário, manter as demais analistas em cópia. *Cobertura (telhado) de Postos de Combustiveis na AKAD é considerada como edificações abertas e ou semi-abertas e não tem amparo técnico na Garantia de Vendaval Utilizar os modelos de carta recusa da AKAD e enviar para validação prévia do analista. Obrigatório utilizar apenas os seguintes termos para encerramento: 1. Recusa Técnica: Sinistros sem cobertura. 2. Encerrado por falta de documentos: Sinistros encerrados por pendência documental. 3. Prejuízo abaixo da franquia: Quando o dano não atinge o valor da franquia. 4. Abertura indevida: Erro de apólice ou necessidade de troca de registro.
A5: Alba- Aliança da Bahia | B5: Sim | C5: Padrão nº da Seguradora e/ou Ticket / Nome do segurado / Nº Addvalora | D5: Para unidade UGC 2 - Seguradora criou e-mail Regulacao@alba.com.br (Para acionamentos e tratativas no decorrer do processo), copiar o analista também. | E5: Orientação : Manter contato imediato após o recebimento do acionamento/ mantendo todos os envolvidos em cópia. | F5: Conforme agendamento / apresentar a sintese até 24h após a vistoria ( dia util) | G5: Até 4 dias após a vistoria (confirmar SLA estipulada em contrato) | H5: Até 5 dias após último documento | I5: UGC 2 - Simplificado com logo Addvalora e ALBA | J5: Sim | K5: A cada 10 dias | L5: 90 dias | M5: Conforme apólice | N5: E-mail para analista para ver se levanta o VR para prejuízos de até 5% do Valor em Risco Declarado ou atuar conforme particularidades da apólice Obs. Tem apólice que até determinado valor não apura o VR | O5: Sem informação / E-mail para o analista | P5: Sem informação | Q5: Sempre enviar para validação da Seguradora, caso estejam de acordo , seguiremos com envio e apresentação ao segurado. | R5: Após a validação da Seguradora , submeteremos ao segurado o Demonstrativo e termo de acordo. | S5: não | T5: não | U5: Sem orientação a respeito | V5: Sem orientação a respeito | W5: Sem orientação a respeito | X5: Não | Y5: Sim | Z5: O login foi liberado, por enquanto, apenas para a usuária Katia Camillo (UGC2). Estamos auxiliando a seguradora no início do uso do sistema. Os procedimentos serão compartilhados com os demais quando o sistema estiver 100% funcional ou de acordo com a necessidade das equipes. A emissão das Notas Fiscais de Honorários deverá ser realizada de forma individualizada por processo de sinistro.
A6: Alianz | B6: Sim | C6: Sim /Seguir padrão da Addvalora | D6: Sem orientação a respeito | E6: Orientação : Manter contato imediato após o recebimento do acionamento | F6: Conforme agendamento / apresentar a sintese até 48h após a vistoria | G6: Até 7 dias após a vistoria | H6: Até 5 dias após último documento | I6: Não. Contudo, usamos um modelo simplificado | J6: Não. Vamos seguir a sugestão e inserir cronologia. | K6: Sugestão: Reiterar a cada 10 dias | L6: Sugestão: Confirmar com analista após 75 dias, se da continuidade ao processo | M6: Conforme apólice | N6: E-mail para analista para ver se levanta o VR para prejuízos de até 5% do Valor em Risco Declarado ou atuar conforme particularidades da apólice Obs. Tem apólice que até determinado valor não apura o VR | O6: E-mail para o analista | P6: Sim | Q6: Ver com o analista | R6: Não | S6: Sim | T6: Sim | U6: Não. Relatório Final inserido em Sistema. Time Sheet inserido em sistema. | V6: Não. Faturamento por lote | W6: Tabela Detalhada de Apuração de Prejuízos | X6: Sim | Y6: Não | Z6: *É muito importante que seja gerada uma nova versão de relatório preliminar toda vez que ocorra alguma atualização importante, tais como, alterações de estimativas e detalhes importantes quanto à cobertura. *O sistema deve ser utilizado para inserir tanto os Relatórios quanto a documentação relativa ao faturamento de honorários e despesas.Mesmo assim, deve ser enviado também aos cuidados do analista via e mail. Encaminhar e mail informando que o processo foi finalizado no sistema. *Na realização da 1ª Vistoria, devera ser entregue o formulário " Termo de Autorização de Pagamento de Sinistro mediante Crédito em Conta" a ser preenchido pelo Segurado. Essa solicitação deverá ser incluída em nossa "Relação de Documentos". *O Sistema deve ser alimentado após o retorno da vistoria e na conclusão da Regulação. * O sistema tem manual  Nomear os documentos que são indexados no sistema.  Atentar-se às solicitações dos analistas feitas através do painel de avisos do sistema.
A7: Avla Seguradora | B7: Não | C7: Seguir padrão da Addvalora | D7: Manter o e-mail "sinistrobr.property@avla.com" em todas tratativas | E7: Orientação : Manter contato imediato após o recebimento do acionamento | F7: Conforme agendamento / apresentar a sintese até 48h após a vistoria | G7: Até 5 dias após a vistoria | H7: Até 5 dias após último documento | I7: Não | J7: Sim | K7: Sugestão: Reiterar a cada 10 dias | L7: Sugestão: Confirmar com analista após 75 dias, se da continuidade ao processo | M7: Conforme apólice | N7: E-mail para analista para ver se levanta o VR para prejuízos de até 5% do Valor em Risco Declarado ou atuar conforme particularidades da apólice Obs. Tem apólice que até determinado valor não apura o VR | O7: E-mail para o analista | P7: Não | Q7: Ver com o analista | U7: Sem orientação a respeito | V7: Sem orientação a respeito | W7: Sem orientação a respeito | X7: Não | Y7: Sim
A8: Axa Seguros | B8: Sim | C8: Não/Inserir somente nº Addvalora | D8: Sim | E8: Orientação : Manter contato imediato após o recebimento do acionamento. | F8: Conforme agendamento / apresentar a sintese até 48h após a vistoria | G8: Até 2 dias após a vistoria | H8: Até 5 dias após último documento | I8: Sim. Utilizamos modelo simplificado | J8: Sim | K8: A cada 7 dias (UGC) | L8: 75 dias informar o analista que indicará o prazo adcional na reiteração. (UCG) | M8: Conforme apólice | N8: E-mail para analista para ver se levanta o VR para prejuízos de até 5% do Valor em Risco Declarado ou atuar conforme particularidades da apólice Obs. Tem apólice que até determinado valor não apura o VR | O8: Sim | P8: E-mail para área de Salvado e Analista (salvados.br@axa.com) | Q8: Não /Ver com o analista | R8: Não | S8: Sim | T8: Sim | U8: Sim. Inserir no sistema da seguradora | V8: Sim: anexadas no GIS em até 1 dia útil ao dia seguinte do envio do relatório final | W8: Formulário Guarda de Salvados | X8: Não | Y8: Sim | Z8: *Tem informações obrigatorias a ser inseridas nos relatórios (vide Baruc) *Modelo padrão da Seguradora para Relatorio Preliminares, Finais, Ata de Vistoria e Relatório Fotografico. Para os ramos (Riscos Nomeados/ Riscos Operacionais/ Riscos de Engenharia), será mantido o modelo da Addvalora. *A indicação da região para deslocamento, quando do aviso de sinistro, poderá ser negociada com a Cia., desde que seja apresentada justificativa plausível (Ex. robustez necessária / regulador com mais expertise devido ao tipo de sinistro / cliente especial / etc); *E-mail: salvados.br@axa.com , copiando sempre o analista do processo. * Para carteira do Posto Ipiranga ver as condições e prazos diferenciados; * Criar tarefa para o analista no sistema ao inserir os relatórios * Continuar enviando os relatórios também por e-mail ao analista * Tem manual do sistema As NFs de Honorários devem ser enviadas e anexadas no GIS em até 1 dia útil ao dia seguinte do envio do relatório final
A9: Berkley Seguros | B9: Não | C9: Seguir padrão da Addvalora | D9: Sem orientação a respeito | E9: Orientação : Manter contato imediato após o recebimento do acionamento | F9: Conforme agendamento / apresentar a sintese até 48h após a vistoria | G9: Até 7 dias após a vistoria | H9: Até 7 dias após último documento | I9: Não | J9: Sim | K9: Sem orientação Sugestão: Reiterar a cada 10 dias | L9: Sem informação / Sugestão: Confirmar com analista após 75 dias, se da continuidade ao processo | M9: Conforme apólice | N9: E-mail para analista para ver se levanta o VR para prejuízos de até 5% do Valor em Risco Declarado ou atuar conforme particularidades da apólice Obs. Tem apólice que até determinado valor não apura o VR | O9: Sem informação / E-mail para o analista | P9: Sem informação | Q9: Sem orientação / ver com o analista | U9: Sem orientação a respeito | V9: Sem orientação a respeito | W9: Sem orientação a respeito | X9: Não | Y9: Sim | Z9: *Relatórios Preliminares 2,3 4, .... : A cada 30 dias, se houver informações que justifiquem, ou sempre que houver fatos relevantes, como alteração de Estimativa de Indenização
A10: BMG Seguros | B10: Não | C10: Não/Inserir somente nº Addvalora | D10: Sim | E10: Orientação : Manter contato imediato após o recebimento do acionamento | F10: Conforme agendamento / apresentar a sintese até 48h após a vistoria | G10: Até 5 dias após a vistoria | H10: Até 5 dias após último documento | I10: Não | J10: Sim | K10: A cada 15 dias | L10: 90 dias | M10: Conforme apólice | N10: E-mail para analista para ver se levanta o VR para prejuízos de até 5% do Valor em Risco Declarado ou atuar conforme particularidades da apólice Obs. Tem apólice que até determinado valor não apura o VR | O10: Sem informação / E-mail para o analista | P10: Sem informação | Q10: Não /Ver com o analista | R10: Sim | S10: Não | T10: Não | U10: Não | V10: Não | W10: *Autorização de crédito *Formulário de conformidade | X10: Sim | Y10: Sim | Z10: *É muito importante que seja gerada uma nova versão de relatório preliminar toda vez que ocorra alguma atualização importante, tais como, alterações de estimativas e detalhes importantes quanto à cobertura. *Tanto os Relatórios quanto a documentação relativa ao faturamento de honorários e despesas.Mesmo assim, deve ser enviado também aos cuidados do analista via e mail. * Reiteração de documentos a cada 15 dias
A11: Bradesco Seguros | B11: Sim | C11: Sem orientação a respeito Seguir padrão da Addvalora | D11: Sem orientação a respeito | E11: Orientação : Manter contato imediato após o recebimento do acionamento | F11: Conforme agendamento / apresentar a sintese até 48h após a vistoria | G11: Até 5 dias após a vistoria | H11: Até 5 dias após último documento | I11: Não | J11: Sim | K11: Sem orientação Sugestão: Reiterar a cada 10 dias | L11: Sem informação / Sugestão: Confirmar com analista após 75 dias, se da continuidade ao processo | M11: Conforme apólice | N11: E-mail para analista para ver se levanta o VR para prejuízos de até 5% do Valor em Risco Declarado ou atuar conforme particularidades da apólice Obs. Tem apólice que até determinado valor não apura o VR | O11: Sem informação / E-mail para o analista | P11: Sem informação | Q11: Sem orientação / ver com o analista | R11: Sim | S11: Não | T11: Sim | U11: Sem orientação a respeito | V11: Sem orientação a respeito | W11: *Autorização para crédito em conta *Termo de guarda de salvados | X11: Não | Y11: Sim | Z11: *A Bradesco também aplica depreciação sobre Mão-de-Obra. *na apuração dos prejuízos e no cálculo da indenização para a cobertura de Roubo, que prevê limitação por unidade sinistrada e proporcionalização das franquias. Para este cálculo, devemos utilizar um quadro disponibilizado pela Bradesco. * Para os sinistros de Danos Elétricos, concluídos a partir do dia 15/04/2019, dos ramos: Residencial, Condomínio e Empresarial, que tenham ocorrido nas cidades (localizadas no Nordeste) elencadas na 2ª aba desta planilha. Assim, as Reguladoras de Sinistros devem orientar os Corretores e/ou Segurados, durante a regulação, que os bens sinistrados, reconhecidamente amparados pelo seguro e que por ventura não compense a sua recuperação (Perda total), deverão ser preservados, conforme previsto nas condições do seguro, para que no final do processo (após a indenização) sejam recolhidos por uma empresa contratada da Bradesco Auto/RE para a destinação adequada. Após a indenização, a empresa recicladora contratada fará o contato com o Segurado visando agendar a data de recolhimento dos salvados, seja no local do sinistro ou na assistência técnica. As Reguladoras de Sinistros deverão informar detalhadamente no Relatório de Regulação a descrição dos salvados de forma completa (quantidade, descrição, marca, modelo e n.º de série) e incluir fotografia (se possível). *Antes de "enviar para análise" no SARE, o Relatório Final e o Time Sheet devem ser submetidos a prévia análise do analista da Cia. Seguradora para aprovação. *Novos procedimentos: 1) Imediatamente após receber pedidos de reaberturas com envio de documentos que estavam pendentes, seja enviado pelo segurado ou pelo corretor, a reguladora deverá comunicar por e-mail ao respectivo supervisor do pro 2) A reguladora deverá responder ao segurado e/ou corretor que os documentos A, B e C foram recebidos e serão analisados por um prazo máximo de 5 dias corridos para que eles tenham uma posição se os documentos são suficientes para reabertura do processo ou não; 2.1) Caso negativo, o segurado e/ou corretor serão informados quais documentos ainda permanecem pendentes e esta mensagem também deverá ser incluída pelo supervisor no SARE. 2.2) Caso positivo, a reguladora deverá solicitar a reabertura do processo no SARE para o respectivo Supervisor para inclusão de Adendo RRS, bem como informar o valor da reserva a ser constituída. Mesmo com processo encerrado no SARE, como tudo estará registrado pelo supervisor, a Central terá acesso ao movimento dos processos.
A12: Chubb Seguros | B12: Sim | C12: Não/Inserir somente nº Addvalora | D12: Sim. Os relatórios devem ser enviados para sinistro.sme@chubb.com, copiando o analista | E12: Orientação : Manter contato imediato após o recebimento do acionamento | F12: Conforme agendamento / apresentar a sintese até 48h após a vistoria | G12: Até 5 dias após a vistoria | H12: Até 5 dias após último documento | I12: Não | J12: Sim | K12: A cada 15 dias | L12: 30 dias (Regulação) + 30 dias (Liquidação). | M12: Conforme apólice | N12: E-mail para analista para ver se levanta o VR para prejuízos de até 5% do Valor em Risco Declarado ou atuar conforme particularidades da apólice Obs. Tem apólice que até determinado valor não apura o VR | O12: Sim | P12: Não / Enviar e-mail para salvados-singrandesriscos@Chubb.com com cópia ao analista do sinistro. | Q12: 1-Em caso de Property não apresentar. 2- Para processo SME não apresentar. | R12: Sim | S12: Não | T12: Sim | U12: Não | V12: Não | W12: *Formulário de Salvados *Autorização de crédito *Formulário de conformidade | X12: Sim | Y12: Sim | Z12: *Para envio de Relatórios ao analista, deve copiar o e-mail sinistro.sme@chubb.com *No corpo do e-mail, deve estar explícita a informação sobre o tipo de relatório enviado à Chubb acompanhado dos seguintes itens adicionais: * Nomear relatórios conforma padrão da seguradora, conforme exemplos: 01_RegulacaoPreliminar_“Ordem de Pagamento SIS , 02_RegulacaoFinal_“Ordem de Pagamento SIS *No corpo do e-mail, deve estar explícita a informação sobre o tipo de relatório enviado à Chubb acompanhado dos seguintes itens adicionais: -Tipo de Relatório -Data de Entrega do último documento fornecido pelo segurado/corretor -Discriminação (Boletim de Ocorrência, por exemplo) -SLA *Nos casos de SME fica mantido o procedimento de envio do demonstrativo de apuração dos prejuízos ao segurado e corretor. Ressaltando que em todos os casos deve ser observado o texto a seguir para evitarmos transtornos junto ao cliente: “Declaro ainda, estar ciente de que o presente termo não implica, por parte da Seguradora, na obrigação do pagamento da indenização pelo sinistro reclamado, a qual fica sujeita às Condições Contratuais, eventuais limitações (tal como o Limite Máximo de Indenização) e eventuais deduções (tais como a franquia, salvados, depreciação e rateio), que regem o contrato de seguro.” O demonstrativo e termo de ciência dos valores não deve ser contabilizado como data de último documento, desta forma, não é obrigatório assinatura do segurado com a concordância de valores. Toda a comunicação com a analista Marina Dantas deve seguir critérios específicos: Não copiar em e-mails de rotina, como solicitações e reiterações de documentos ou envio de ata para assinatura. Copiar quando for necessária sua intervenção, parecer ou esclarecimento técnico. Copiar no envio dos seguintes documentos: ata já assinada, relatório fotográfico, relatório preliminar, relatório final e notas fiscais. Nesses casos, manter também em cópia o e-mail sinistro.sme@chubb.com Envio obrigatório de relatório semanal todas as segundas-feiras com o estágio atualizado de cada sinistro em andamento. O prazo de regulação/liquidação suspende-se por no máximo 2 (duas) vezes para solicitação de documentos. Relatórios finais devem conter: coberturas afetadas, limites, memória de cálculo detalhada (franquias, juros, atualização) e fundamentação fática/legal em caso de recusa.
A13: Excelsor Seguros | B13: Não | C13: Sim /Seguir padrão da Addvalora | D13: Sim / Também a caixa departamental (sinistros@excelsior.com.br) | E13: Orientação : Manter contato imediato após o recebimento do acionamento | F13: Conforme agendamento / apresentar a sintese até 48h após a vistoria | G13: Até 7 dias após a vistoria | H13: Até 7 dias após último documento | I13: Não | J13: Sim | K13: Sem orientação Sugestão: Reiterar a cada 10 dias | L13: Sem informação / Sugestão: Confirmar com analista após 75 dias, se da continuidade ao processo | M13: Conforme apólice | N13: E-mail para analista para ver se levanta o VR para prejuízos de até 5% do Valor em Risco Declarado ou atuar conforme particularidades da apólice Obs. Tem apólice que até determinado valor não apura o VR | O13: E-mail para o analista | P13: Sem informação | Q13: Solicitar aprovação ao analista | R13: Não | S13: Sim | T13: Não | U13: Não | V13: Não | W13: Carta de Posicionamento (Minuta enviada para o analista) | X13: Não | Y13: Sim | Z13: *Relatórios Preliminares 2, 3, 4....... : A cada 30 dias, se houver informações que justifiquem, ou sempre que houver fatos relevantes, como ateração de Estimativas de Indenização *Caixa departamental: sinistros@excelsiorseguros.com.br
A14: FairFax Seguros | B14: Não | C14: Não /Inserir somente nº Addvalora no final | D14: Copiar a caixa departamental (sin-property@fairfax.com.br) | E14: Orientação : Manter contato imediato após o recebimento do acionamento | F14: Conforme agendamento / apresentar a sintese até 48h após a vistoria | G14: Até 7 dias após a vistoria | H14: Até 7 dias após último documento | I14: Não | J14: Sim | K14: Sugestão: Reiterar a cada 10 dias | L14: 90 dias informar ao analista e solicitar prazo para encerramento (costumam dar mais 30 dias) | M14: Conforme apólice | N14: E-mail para analista para ver se levanta o VR para prejuízos de até 5% do Valor em Risco Declarado ou atuar conforme particularidades da apólice Obs. Tem apólice que até determinado valor não apura o VR | O14: E-mail para o analista + corporativo | P14: E-mail | Q14: Solicitar aprovação ao analista | R14: Demonstrativo de prejuízos | S14: Termo de quitação | T14: Não | U14: Não. Encaminhar e-mail para aprovação do TS | V14: Não. Nota Fiscal segue aprós aprovação do TS | W14: Autorização para Crédito em conta | X14: Não | Y14: Sim | Z14: * Não será necessário o envio de e-mail de agradecimento * Para os sinistros em que haja o envio de relatório preliminar, final ou adendo. Sugerimos, incluir nas primeiras linhas do e- mail um recorte/print do Cálculo de reserva, que constará no relatório em anexo, isso facilitará a identificação de casos de maiores perdas, logo ao receber o e-mail. *O assunto dos e-mails enviados para a Fairfax não pode ser alterado para o padrão da Addvalora, podemos apenas inserir a referência da Addvalora, pois tem restrições de caracteres no referido campo. *A Seguradora possui e mail corporativo: sin-property@fairfax.com.br. *Todas as tratativas com à Seguradora devem ser feitas pelo e mail corporativo, NUNCA devemos enviar os e mails diretamente para o Analista., salvo na UGR, conforme orientação do Clark, sempre copiam, além da caixa departamental, o analista do processo e na maioria das vezes, o José Eduardo e o José Luiz (por solicitação dos próprios). *Quando enviar e-mail diretamente para o Segurado (agendamento da vistoria ou outros por orientação do Corretor) deve-se colocar o sin-property em cópia normal.
A15: Fator | B15: Não | C15: Padrão nº da Seguradora e/ou Ticket / Nome do segurado / Nº Addvalora | D15: Sim / Incluir obrigatoriamente a chave: docsin@fatorseguradora.com.br | E15: Orientação : Manter contato imediato após o recebimento do acionamento/ mantendo todos os envolvidos em cópia. | F15: Conforme agendamento / apresentar a sintese até 24h após a vistoria ( dia util) | G15: Até 3 dias após a vistoria | H15: Até 7 dias após último documento | I15: Modelo Addvalora (Property) | J15: Sim | K15: A cada 15 dias | L15: Referido prazo de 90 dias, com a anuência expressa da Seguradora, deverá ser elaborada correspondência, informando o encerramento do sinistro no prazo de 10 (dez) dias. | M15: Conforme apólice | N15: E-mail para analista para ver se levanta o VR para prejuízos de até 5% do Valor em Risco Declarado ou atuar conforme particularidades da apólice Obs. Tem apólice que até determinado valor não apura o VR | O15: Sem informação / E-mail para o analista | P15: Não há | Q15: Sempre enviar para validação da Seguradora, caso estejam de acordo , seguiremos com envio e apresentação ao segurado. | R15: Sim | S15: sim | T15: sim | U15: sim | V15: Tabela pode enviar o RF + NF dos honorários. | W15: Papel timbrado | X15: Sim | Y15: Não | Z15: *Caixa departamental - sinistros@fatorseguradora.com.br; *Todos os sinistros que envolvam valores de prejuízos relevantes, deverão ser discutidos previamente com o analista responsável pelo processo na Fator antes da emissão do relatório intermediário/preliminar. 1. Informar imediatamente o recebimento do último documento. 2. Enviar planilha de controle (Anexo 1) até o 5º dia útil do mês. 3. Follow-up judicial a cada 60 dias. 4. Resposta ao segurado: sempre "Em Análise". Sempre que houver o recebimento do último documento necessário à análise do sinistro, deverá ser enviado e-mail ao analista responsável da Seguradora, informando que a documentação necessária foi integralmente apresentada, bem como a data de recebimento do último documento. Da mesma forma, caso sejam identificadas, após a vistoria e/ou contato preliminar com o Segurado ou seu Representante, dúvidas ou indícios quanto ao enquadramento do evento nas coberturas contratadas, a Fator deverá ser comunicada com a maior brevidade possível.
A16: FM Global | B16: Não | C16: Sem orientação a respeito Seguir padrão da Addvalora | D16: Sim | E16: Orientação : Manter contato imediato após o recebimento do acionamento | F16: Conforme agendamento / apresentar a sintese até 48h após a vistoria | G16: Até 5 dias após a vistoria | H16: Até 5 dias após último documento | I16: Não | J16: Sim | K16: Sem orientação Sugestão: Reiterar a cada 10 dias | L16: Sem informação / Sugestão: Confirmar com analista após 75 dias, se da continuidade ao processo | M16: Conforme apólice | N16: E-mail para analista para ver se levanta o VR para prejuízos de até 5% do Valor em Risco Declarado ou atuar conforme particularidades da apólice Obs. Tem apólice que até determinado valor não apura o VR | O16: Sem informação / E-mail para o analista | P16: Sem informação | Q16: Sem orientação / ver com o analista | U16: Sem orientação a respeito | V16: Sem orientação a respeito | W16: Sem orientação a respeito | X16: Não | Y16: Sim
A17: Generali Seguros | B17: Sim | C17: Não / Seguir padrão orientado pela seguradora | D17: Sim | E17: Orientação : Manter contato imediato após o recebimento do acionamento | F17: Conforme agendamento / apresentar a sintese até 24h após a vistoria | G17: Até 48 horas da realização da vistoria | H17: Até 5 dias após último documento | I17: Não | J17: Sim | K17: A cada 15 dias | L17: 90 dias | M17: Conforme apólice | N17: E-mail para analista para ver se levanta o VR para prejuízos de até 5% do Valor em Risco Declarado ou atuar conforme particularidades da apólice Obs. Tem apólice que até determinado valor não apura o VR | O17: E-mail para o analista / inserção no sistema | P17: Sem informação | Q17: Sim | R17: Sim | S17: sim | T17: Não | U17: Apresentar junto ao relatório final a estimativa do TS | V17: Não | W17: Não | X17: Não | Y17: Sim | Z17: Padrão de assunto de e-mail - E mails enviados para a Generali devem seguir o seguinte padrão: Agendamento Vistoria: Sinistro xxxxxx - Segurado: < Nome do Segurado> - Apólice: xxxxxx - Aviso: xxxxxxx Relatório Preliminar: Relatório Preliminar - Sinistro: xxxxx - Segurado: < Nome do Segurado> / Relatório Final: Relatório Final - Sinistro: xxxxx - Segurado: < Nome do Segurado > * No caso do Relatório Final, os arquivos devem ser enviados na seguinte ordem: NF honorarios e recibo despesas, Relatório de Regulação, e por último os anexos. Honorários e Despesas de Regulação: A partir de 13 de setembro de 2024, é obrigatório incluir nos relatórios preliminares, finais e loss advices os valores estimados de honorários e despesas de regulação de forma separada. Esta medida visa aprimorar o controle das reservas financeiras.
A18: HDI Global | B18: Sim | C18: Seguir padrão da Seguradora e acrescentar n° Addvalora | D18: Sim | E18: Orientação : Manter contato imediato após o recebimento do acionamento | F18: Conforme agendamento / apresentar a sintese até 48h após a vistoria | G18: Até 5 dias após a vistoria | H18: Até 5 dias após a vistoria | I18: Não | J18: Sim | K18: Semanalmente | L18: Compeltado 75 dias encaminhar ultima cobrnça com prazo de 15 para finalização ADM. | M18: Conforme apólice | N18: E-mail para analista para ver se levanta o VR para prejuízos de até 5% do Valor em Risco Declarado ou atuar conforme particularidades da apólice Obs. Tem apólice que até determinado valor não apura o VR | O18: Sem informação / E-mail para o analista | P18: Sem informação | Q18: Com anuência da seguradora | R18: Sim | S18: Sim | T18: Não | U18: Sim | V18: Sim | W18: Autorização para Crédito em conta | X18: Não | Y18: Sim | Z18: *Se receber documentos tem até 48 horas para responder o corretor sobre pendências * Caso seja necessário o envio de relatório traduzido, este deverá ser encaminhado em até 7 dias da solicitação da HDI Global. *Caso seja necessário o envio de adendo aos relatórios, este deverá ser encaminhado em até 05 dias da solicitação da HDI Global. * Inserir nº Call Center e nº Hans nos Relatórios * Para o preenchimento do sistema, ver manual *Inserir o número da reiteração de documentos a cada envio de e-mail ao segurado /corretor Ao finalizar o processo: 1) Quando da finalização do processo, verificar se a pessoa que assinará a TED tem poderes e se a documentação encaminhada atende os requisitos. 2) Em caso de procuração, favor se atentar para a validade do documento; 3) Em alguns casos, há necessidade de assinatura de 02 ou mais representantes da Empresa, portanto, a documentação encaminhada deverá atender estes requisitos; 4) Quando do encerramento do processo pelo tempo decorrido, o regulador deverá mencionar todas as datas de reiterações e os documentos ainda pendentes Modelo de Relatório: Devem ser enviados no modelo "Draft" (com marca d’água) para validação prévia do analista. Conteúdo: Não devem conter opiniões sobre enquadramento de coberturas. Texto Obrigatório: Incluir ao final de cada relatório o texto padrão de isenção de responsabilidade da seguradora. Relatórios Traduzidos: Prazo de envio em até 2 dias da solicitação. Confirmação de Documentos: Prazo de 48 horas para confirmar recebimento e apontar pendências ao corretor/segurado. Reforma Tributária (2026): Notas fiscais a partir de 01/01/2026 devem destacar IBS/CBS (alíquota teste 1%) conforme nova cláusula 1.4 do contrato. Plantão de Emergência: Em recessos (como final de ano), utilizar os contatos específicos das áreas (Corporate: Diogo/Edmilson/Jorge/Thais; Massificados: Klauss/Toninho/Eliomar; Grandes Riscos: Luciano). Solicitação de Documentos (não é necessário solicitar): Formulário Cadatral dos Beneficiários, RG/CPF do Segurado, RG/CPF do Beneficiário, Cópia do Cartão CNPJ, Contrato Social, RG/CPF dos Sócios da Empresa. Solicitar contrato social somente se for necessário comprovação de vínculo se o comprovante de endereço não estiver nominal ao segurado. Não copiar os Analistas em todas as trocas de e-mails: Apenas naqueles em que for preciso um retorno dele; Envio da DRL: Utilizar o sistema da HDI, inclusive, para as reiterações; Reiterações: frequência semanal; Quadro Demonstrativo de Apuração: Indexar no sistema apenas após o “de acordo” do Corretor/Segurado; Quadro Demonstrativo de Apuração: Alçada de R$ 50k para envio sem prévia avaliação do Analista da Cia; Solicitação de Documentos: enviada após a validação do Analista da Cia ao Informe Preliminar. Documentação SUSEP: Não há necessidade (exceção: Para os sinistros de Danos Elétricos há necessidade do envio do comprovante de endereço (conta de luz emitida pela concessionária de energia)). Não utilizar o seguinte texto: Documentos necessários para a regulação solicitados ao Corretor nesta data. Orientação ao RCG: a regulação de sinistros envolvendo automóveis está sendo realizada pela própria Seguradora. Portanto, orienta-se questionar a companhia assim que o acionamento for recebido, registrando essa informação imediatamente no sistema. Sempre que a regulação exigir mais de 40 horas dedicadas, o colaborador deve obrigatoriamente acionar o contato na Área de Sinistros da Seguradora.
A19: HDI Seguros | B19: Sim | C19: Seguir padrão da Addvalora | D19: sim | E19: Orientação : Manter contato imediato após o recebimento do acionamento e atualizar o sistema da seguradora com a data da vistoria | F19: Conforme agendamento / apresentar a sintese até 48h após a vistoria | G19: Até 48 horas após a vistoria | H19: Até 5 dias após último documento | I19: Não | J19: Sim | K19: Semanalmente | L19: Sugestão: Confirmar com analista após 75 dias, se da continuidade ao processo | M19: Conforme apólice | N19: E-mail para analista para ver se levanta o VR para prejuízos de até 5% do Valor em Risco Declarado ou atuar conforme particularidades da apólice Obs. Tem apólice que até determinado valor não apura o VR | O19: Sim | P19: E-mail para analista | Q19: Não /Ver com o analista | R19: Sim / mas após aval do analista | S19: Sim | T19: Não | U19: Inserimos no sistema após envio do final | V19: Não | W19: Não | X19: Não | Y19: Sim | Z19: * Tem procedimentos para preenchimento da agenda no sistema ( manual no Baruc) *Tem regra para aplicação de franquia (LMI) e salvados * Tem que constar na ata ou preliminar se ter algum tipo de seguro inclusive habitacional quando for o caso. Modelo de Relatório: Devem ser enviados no modelo "Draft" (com marca d’água) para validação prévia do analista. Conteúdo: Não devem conter opiniões sobre enquadramento de coberturas. Texto Obrigatório: Incluir ao final de cada relatório o texto padrão de isenção de responsabilidade da seguradora. Relatórios Traduzidos: Prazo de envio em até 2 dias da solicitação. Confirmação de Documentos: Prazo de 48 horas para confirmar recebimento e apontar pendências ao corretor/segurado. Reforma Tributária (2026): Notas fiscais a partir de 01/01/2026 devem destacar IBS/CBS (alíquota teste 1%) conforme nova cláusula 1.4 do contrato. Plantão de Emergência: Em recessos (como final de ano), utilizar os contatos específicos das áreas (Corporate: Diogo/Edmilson/Jorge/Thais; Massificados: Klauss/Toninho/Eliomar; Grandes Riscos: Luciano). Solicitação de Documentos (não é necessário solicitar): Formulário Cadatral dos Beneficiários, RG/CPF do Segurado, RG/CPF do Beneficiário, Cópia do Cartão CNPJ, Contrato Social, RG/CPF dos Sócios da Empresa. Solicitar contrato social somente se for necessário comprovação de vínculo se o comprovante de endereço não estiver nominal ao segurado. Não copiar os Analistas em todas as trocas de e-mails: Apenas naqueles em que for preciso um retorno dele; Envio da DRL: Utilizar o sistema da HDI, inclusive, para as reiterações; Reiterações: frequência semanal; Quadro Demonstrativo de Apuração: Indexar no sistema apenas após o “de acordo” do Corretor/Segurado; Quadro Demonstrativo de Apuração: Alçada de R$ 50k para envio sem prévia avaliação do Analista da Cia; Solicitação de Documentos: enviada após a validação do Analista da Cia ao Informe Preliminar. Documentação SUSEP: Não há necessidade (exceção: Para os sinistros de Danos Elétricos há necessidade do envio do comprovante de endereço (conta de luz emitida pela concessionária de energia)). Não utilizar o seguinte texto: Documentos necessários para a regulação solicitados ao Corretor nesta data. Orientação ao RCG: a regulação de sinistros envolvendo automóveis está sendo realizada pela própria Seguradora. Portanto, orienta-se questionar a companhia assim que o acionamento for recebido, registrando essa informação imediatamente no sistema.
A20: Junto Seguros | B20: Não | C20: Sem orientação a respeito Seguir padrão da Addvalora | D20: Não | E20: Orientação : Manter contato imediato após o recebimento do acionamento | F20: Conforme agendamento / apresentar a sintese até 24h após a vistoria | G20: Até 5 dias após a vistoria | H20: Até 5 dias após último documento | I20: Não | J20: Sim | K20: Sem orientação Sugestão: Reiterar a cada 10 dias | L20: Sem informação / Sugestão: Confirmar com analista após 75 dias, se da continuidade ao processo | M20: Conforme apólice | N20: E-mail para analista para ver se levanta o VR para prejuízos de até 5% do Valor em Risco Declarado ou atuar conforme particularidades da apólice Obs. Tem apólice que até determinado valor não apura o VR | O20: Sem informação / E-mail para o analista | P20: Sem informação | Q20: Sem orientação /Ver com o analista | U20: Sem orientação a respeito | V20: Sem orientação a respeito | W20: Sem orientação a respeito | X20: Não | Y20: Sim
A21: Liberty Seguros | B21: Sim | C21: Sim /Seguir padrão da Addvalora | D21: Sim | E21: Orientação : Manter contato imediato após o recebimento do acionamento | F21: Conforme agendamento / apresentar a sintese até 48h após a vistoria | G21: Até 7 dias após a vistoria | H21: Até 7 dias após último documento | I21: Não | J21: Sim | K21: Sugestão: Reiterar a cada 10 dias | L21: Sugestão: Confirmar com analista após 75 dias, se da continuidade ao processo | M21: Conforme apólice | N21: E-mail para analista para ver se levanta o VR para prejuízos de até 5% do Valor em Risco Declarado ou atuar conforme particularidades da apólice Obs. Tem apólice que até determinado valor não apura o VR | O21: E-mail para o analista | P21: Sem informação | Q21: Não /Ver com o analista | R21: Não | S21: Sim | T21: Não | U21: Sem orientação a respeito | V21: Sem orientação a respeito | W21: Sem orientação a respeito | X21: Não | Y21: Sim | Z21: *Relatórios Finais com apuração de indenização deveram vir acompanhados pelo Formulário Padrão da Liberty, Formulário Susep 445 " cadastro de beneficiário" *Fornece informações até o 2º dia útil de cada semana " informações sobre o desenvolvimento de Trabalhos de Regulação". *Relatórios Preliminares 2,3,4....: A cada 30 dias, se houver informações que justifiquem, ou sempre que houver fatos relevantes, como alteração de Estimativas de Idenização. * Link de acesso ao Portal Yelum (Liberty): https://www.portaldesegurosyelum.com.br/Inicio/login_prestadores.aspx
A22: Mapfre | B22: Sim | C22: Sem orientação a respeito Seguir padrão da Addvalora | D22: Sim | E22: Orientação : Manter contato imediato após o recebimento do acionamento | F22: Conforme agendamento / apresentar a sintese até 24h após a vistoria | G22: Até 3 dias após a vistoria | H22: Até 5 dias após último documento | I22: Não | J22: Sim | K22: A cada 15 dias | L22: Passados 90 dias da solicitação inicial dos documentos , consultar a seguradora | M22: Conforme apólice | N22: E-mail para analista para ver se levanta o VR para prejuízos de até 5% do Valor em Risco Declarado ou atuar conforme particularidades da apólice Obs. Tem apólice que até determinado valor não apura o VR | O22: Sim | P22: E-mail para analista | Q22: Não /ver com o analista | R22: Sim / mas após aval do analista | T22: Sim | U22: Sem orientação a respeito | V22: Sem orientação a respeito | W22: Formulário PPE - Pessoa Jurídica e Física / Formulário de Autorização de crédito / Formulário de Identificação dos sócios / Formulário de declaração de Inexistência de outros seguros Demonstrativo de prejuízos / Recibo Quitação | X22: Não | Y22: Sim | Z22: *A Mapfre possui um sistema informatizado semelhante ao nosso, que deve ser alimentado após o retorno da vistoria e quando da conclusão da regulação. É importante o devido registro no sistema deles, já que em caso de inconformidade, o analista não consegue constituir reserva e efetuar o pagamento da indenização e dos honorários. No sistema da Seguradora, devemos preencher apenas as abas denominadas: parecer, valores e documentos. * Inserir o relatório do Firstone somente após a avaliação do analista
A23: Mitsui Seguros | B23: Não | C23: Seguir padrão da Addvalora | D23: Em todas tratativas manter: documentosinistro@msig.com.br | E23: Orientação : Manter contato imediato após o recebimento do acionamento | F23: Conforme agendamento / apresentar a sintese até 48h após a vistoria | G23: Até 5 dias após a vistoria - Prejuizos até R$ 100mil Até 10 dias Prejuízos acima de R$ 100mil | H23: Até 5 dias após último documento - prejuizo até R$ 100mil Até 10 dias após último documento - prejuizo acima de R$ 100mil | I23: Não | J23: Sim | K23: A cada 15 dias e ao completar 75 dias, conceder prazo de +15dias | L23: 75 dias | M23: Conforme apólice | N23: E-mail para analista para ver se levanta o VR para prejuízos de até 5% do Valor em Risco Declarado ou atuar conforme particularidades da apólice Obs. Tem apólice que até determinado valor não apura o VR | O23: E-mail para o analista | P23: Email | Q23: Sim - Até R$ 200 mil - com ressalva a que seguradora fará análise dos valores . Não - Acima de R$ 200 mil | R23: Sim - Até R$ 200mil | S23: Sim | T23: Sim | U23: Sim | V23: Sim. Não colocar a palavra Kit no anexo de honorários e despesas | W23: Termo de Quitação de Sinistro | X23: Não | Y23: Sim | Z23: *Responder e-mails em até 48 horas; *Colocar Relatório, síntese e fotográfico em único arquivo pdf; *Temos liberdade para sugestão de adiantamento mesmo sem solicitação o segurado; * Negativa pode ser adiantada ao corretor antes de submeter a seguradora; *Preliminares II, III, encaminhar e-mail somente ao analista; * Termo de Acordo: incluir texto que os valores serão submetidos para avaliação da Seguradora * Caso receba acionamento que ultrapasse 200km, solicitar aprovação para o analista antes de seguir com o atendimento; *Relatórios Preliminares e Intermediários, o assunto do e-mail deve seguir – Aviso: N° Sinistro (123456) – Sinistro 0118000000 – Segurado ABCD *Relatório Final e Adendo, o assunto do e-mail deve seguir – AVISO 123456 DT_ULTIMO _DOC – DD/MM/AAAA A equipe da Mitsui deve ser copiada em todas as comunicações com o corretor/segurado através do e-mail documentosinistro@msig.com.br. Notas fiscais e despesas devem acompanhar o Relatório Final. Não se deve usar a palavra "Kit" na descrição de honorários e despesas. Ajuste de Reserva: Sempre que houver um ajuste de reserva, é necessário elaborar um relatório preliminar e contatar o analista. Variações de até 20% podem dispensar o relatório, dependendo do valor do prejuízo, mas o contato com o analista é essencial. Peritos: A condução do perito é responsabilidade do regulador, que deve indicar o tipo de perícia necessária. A seguradora cobre os custos de apenas um regulador de campo e um perito por vistoria. Adiantamentos: Os reguladores têm autonomia para sugerir adiantamentos, mesmo sem solicitação, comunicando previamente o analista. Atenção especial para adiantamentos acima de R$ 500.000,00. Termo de Acordo: Para processos de até R$ 200.000,00, o termo deve incluir um texto informando que os valores serão validados pela seguradora. Acima desse valor, o processo deve ser submetido à aprovação prévia da seguradora antes do envio do termo.
A24: Newe | B24: Não | C24: Sem orientação a respeito Seguir padrão da Addvalora | D24: Sem orientação a respeito | E24: Orientação : Manter contato imediato após o recebimento do acionamento | F24: Conforme agendamento / apresentar a sintese até 48h após a vistoria | G24: Até 5 dias úteis nos casos sem perícia e até 10 dias úteis nos casos com perícia. | H24: Até 3 dias úteis após último documento | I24: Não | J24: Sim | K24: Solicitação de documentos: até 24 horas úteis; Análise de documentos: até 7 dias úteis nos casos sem perícia e até 10 dias úteis nos casos com perícia; | L24: 30 dias - NLS | M24: Conforme apólice | U24: Não | V24: Não | Z24: A rotina de faturamento fica padronizada da seguinte forma: Emissão de 1 NF e 1 recibo por mês; Envio das informações para validação até o dia 05 do mês subsequente, no modelo disponibilizado pela Newe; Individualização dos valores por número de sinistro e apólice; Envio com prefixo obrigatório [FATURAMENTO] para os e-mails juridico@neweseguros.com e produtos.juridico@neweseguros.com; Validação pela Newe até o dia 10; e Emissão da NF + recibo com vencimento no dia 20.
A25: Potencial Seguros | B25: Sim | C25: Sem orientação a respeito Seguir padrão da Addvalora | D25: Sem orientação a respeito | E25: Orientação : Manter contato imediato após o recebimento do acionamento | F25: Conforme agendamento / apresentar a sintese até 48h após a vistoria | G25: Até 5 dias após a vistoria | H25: Até 5 dias após último documento | I25: Sim / Tem modelo apenas para exemplos de tópicos a serem utilizados | J25: Sim | K25: Sem orientação Sugestão: Reiterar a cada 10 dias | L25: Sem informação / Sugestão: Confirmar com analista após 75 dias, se da continuidade ao processo | M25: Conforme apólice | N25: E-mail para analista para ver se levanta o VR para prejuízos de até 5% do Valor em Risco Declarado ou atuar conforme particularidades da apólice Obs. Tem apólice que até determinado valor não apura o VR | O25: Sem informação / E-mail para o analista | P25: Sem informação | Q25: Sem orientação /Ver com o analista | U25: Sem orientação a respeito | V25: Sem orientação a respeito | W25: Sem orientação a respeito | X25: Não | Y25: Sim | Z25: *Contato para agendamento de vistoria, indicação de prejuízo em até 48 horas *Emissão de Relatório Final até 05 dias corridos após a entrega do último documento *Tem modelo de planilha de apuração no Baruc RD Valor Atual: Para obtenção do valor atual de equipamentos, o regulador de sinistro deverá além de solicitar as cotações ao segurado, obter também suas próprias cotações no mercado, junto à revendedores de equipamentos iguais ou similares ao sinistrado; - Caso as cotações apresentas pelo segurado estiver de acordo com os valores praticados pelo mercado, considerar esses valores como valor atual - Caso houver discrepância entre as cotações apresentadas pelo segurado, deveremos adotar ou as cotações obtidas pelo regulador de sinistro ou lançar mão de métodos de depreciação constante das condições gerais da apólice (Ross-Heideck) *Sinistro sem Cobertura Técnica: Se por ocasião da pre-análise ou durante a vistoria do regulador de sinistro, em ficando constatado que o evento não possui cobertura técnica na apólice do segurado, o regulador não deverá emitir no momento opinião a respeito da cobertura ou não do sinistro. Contudo, deverá ser solicitado ao segurado somente a documentação mínima necessária para comprovação do sinistro (negativa) e os prejuízos. *Seguradora solicita que a reguladora agilize os processos de sinistros para os casos em que estiver evidente a exclusão da cobertura técnica, não passar ao Segurado “Termo de Acordo de Prejuízos”. Passar apenas um documento denominado “demonstrativo de valores apurados”, sem necessitar pegar o de acordo do segurado e também não solicitar documentos de SUSEP, dados bancários, etc... A documentação para sinistros cuja cobertura estiver flagrantemente excluída, a regulação deverá ser agilizada, não criar expectativa de indenização ao segurado e limitar a solicitar documentos necessários a comprovação de causa, danos e prejuízos. *Não deixar de inserir no corpo do Relatório de Regulação de Sinistros (relatório modelo Pottencial já passado em reunião realizada na Pottencial recentemente), fotografias do equipamento sinistrado, modelo novo, numeração da gravação de chassi legível (não se limitar a plaqueta de identificação do equipamento), se possível número de motor também. Essa numeração deve estar devidamente compatível com a apólice do segurado. Tiveram casos para liquidar que não tinha a fotografia legível da gravação do chassi, apenas a foto da placa de identificação da máquina. Isso pode deixar a Cia. Seguradora vulnerável em alguma situação. * Se atentar para sinistros envolvendo Cortees e Soldas. Texto no Baruc * Nos relatórios, seguir como padrão o capitulo 02 como sendo onde descrevemos o SEGURADO.
A26: QBE Seguros | B26: Não | C26: Sem orientação a respeito Seguir padrão da Addvalora | D26: Sem orientação a respeito | E26: Orientação : Manter contato imediato após o recebimento do acionamento | F26: Conforme agendamento / apresentar a sintese até 48h após a vistoria | G26: Até 5 dias após a vistoria | H26: Sem orientação a respeito/ Considerar até 5 dias após último documento | I26: Não | J26: Sim | K26: Sem orientação Sugestão: Reiterar a cada 10 dias | L26: Sem informação / Sugestão: Confirmar com analista após 75 dias, se da continuidade ao processo | M26: Conforme apólice | N26: E-mail para analista para ver se levanta o VR para prejuízos de até 5% do Valor em Risco Declarado ou atuar conforme particularidades da apólice Obs. Tem apólice que até determinado valor não apura o VR | O26: Sem informação / E-mail para o analista | P26: Sem informação | Q26: Sem orientação /Ver com o analista | R26: Sem orientação a respeito | S26: Sem orientação a respeito | T26: Sem orientação a respeito | U26: Sem orientação a respeito | V26: Sem orientação a respeito | W26: Sem orientação a respeito | X26: Não | Y26: Sim
A27: Sancor Seguros | B27: Sim | C27: Sim/ Seguir padrão da Addvalora | D27: Copiar a Caixa departamental | E27: Orientação : Manter contato imediato após o recebimento do acionamento | F27: Conforme agendamento / apresentar a sintese até 48h após a vistoria | G27: Até 48 horas da realização da vistoria | H27: Até 5 dias após último documento | I27: Não | J27: Sim | K27: A cada 10 dias | L27: 90 dias | M27: Conforme apólice | N27: E-mail para analista para ver se levanta o VR para prejuízos de até 5% do Valor em Risco Declarado ou atuar conforme particularidades da apólice Obs. Tem apólice que até determinado valor não apura o VR | O27: Sem informação / E-mail para o analista | P27: Sem informação | Q27: Sem orientação /Ver com o analista | R27: Sim/ Mas com o aval da da seguradora | U27: Sem orientação a respeito | V27: Sem orientação a respeito | W27: Sem orientação a respeito | X27: Não | Y27: Sim | Z27: Todos os pedidos de aprovação de timesheet devem ser encaminhados ao analista responsável, com o endereço sinistrosdespesas@fatorseguradora.com.br em cópia. *Se não recebermos documentos no prazo de 15/20 dias, podemos apurar e apresentar ao corretor/segurado, para ver se concordamos com os valores, dependendo do caso e tipo de dano. *Sempre que houver a possibilidade de apurar (casos de negativas) sem a solicitação de documentos, devemos fazer a apuração no relatório preliminar ou final, por causa das incidências de casos judiciais. *Em casos como de vendaval (destelhamento), caso o segurado não encaminhe documentos, podemos apurar (com a ajuda dos nossos especialistas) e submeter ao segurado caso ele concorde com os valores, podemos fechar o processo. *Em processos que não há dúvidas ou problemas, podemos encaminhar o Termo de Valores ao corretor/segurado, sem anuência da segurança, porém sempre deixando informado no Termo de Acordo, que os valores serão submetidos para a análise da Seguradora. Caso identifique algum problema, casos que fogem da curva, submeta o Relatório antes de ligar para segurança validar (copiar caixa departamental). *Se não recebermos documentos no prazo de 15/20 dias, podemos apurar e apresentar ao corretor/segurado, para ver se concordamos com os valores, dependendo do caso e tipo de dano.
A28: Sombrero Seguros | B28: Não | C28: Sem orientação a respeito Seguir padrão da Addvalora | D28: Sem orientação a respeito | E28: Orientação : Manter contato imediato após o recebimento do acionamento/ mantendo todos os envolvidos em cópia. | F28: Conforme agendamento / apresentar a sintese até 24h após a vistoria ( dia util) | G28: Até 5 dias após a vistoria | H28: Até 5 dias após último documento | I28: Modelo Addvalora (Property) | J28: Sim | K28: Sem orientação Sugestão: Reiterar a cada 10 dias | L28: Sem informação / Sugestão: Confirmar com analista após 75 dias, se da continuidade ao processo | M28: Conforme apólice | N28: E-mail para analista para ver se levanta o VR para prejuízos de até 5% do Valor em Risco Declarado ou atuar conforme particularidades da apólice Obs. Tem apólice que até determinado valor não apura o VR | O28: Sem informação / E-mail para o analista | P28: E-mail para analista | Q28: Sempre enviar para validação da Seguradora, caso estejam de acordo , seguiremos com envio e apresentação ao segurado. | R28: Sim/ Mas com o aval da da seguradora | S28: sim | T28: sim | U28: Sem orientação a respeito | V28: Tabela pode enviar o RF + NF dos honorários. | W28: Sem orientação a respeito | X28: Não | Y28: Sim
